Workbook

Sheet Suplementos Bocadillos
A1: Nombre | B1: Precio (€) | C1: Nota
A2: Champiñones | B2: 1
A3: Queso | B3: 1.2
A4: Bacon | B4: 1.5
A5: Pan con tomate | B5: 0.15 | C5: Revisar: precio bajo comparado con 'Rodaja pan con tomate' (1,45)
A6: Sin pan con tomate | C6: Sin precio en pantalla (probablemente gratis)
A7: Cebolla (ceba) | B7: 1.1
A8: Al plato | C8: Sin precio en pantalla (probablemente gratis)
A9: Mayonesa | B9: 0.35
A10: Alioli | B10: 0.35
A11: Anchoas | B11: 1.95
A12: Ternera | B12: 2.25
A13: Lomo | B13: 1.85
A14: Hamburguesa | B14: 1.95
A15: Pan planchado | C15: Sin precio en pantalla (probablemente gratis)
A16: Huevo | B16: 1.2 | C16: Revisar: 'Huevo' aparece dos veces con precios distintos
A17: Jamón dulce | B17: 1.15
A18: Lechuga | B18: 1.1
A19: Salsa verde | C19: Sin precio en pantalla (probablemente gratis)
A20: Bien hecho | C20: Sin precio en pantalla (probablemente gratis)
A21: Pimiento | B21: 1.25
A22: Queso brie | B22: 1.75
A23: Ajo y perejil | B23: 0.9
A24: Oliva | B24: 1
A25: Rodaja pan con tomate | B25: 1.45
A26: Rodaja de tomates | B26: 1.1
A27: Jamón salado | B27: 1.2
A28: Piña | B28: 0.8 | C28: Aparece dos veces en la caja con precios distintos
A29: Pollo | B29: 1.75
A30: Piña | B30: 0.9 | C30: Aparece dos veces en la caja con precios distintos
A31: Salsa romesco | B31: 0.9
A32: Atún | B32: 1.1
A33: Hamburguesa picante | B33: 2.05
A34: Salsa rosa | C34: Sin precio en pantalla (probablemente gratis)
A35: Cebolla | B35: 1.1
A36: Tortilla | B36: 1.5
A37: Abierto | C37: Sin precio en pantalla (probablemente gratis)
A38: Hamburguesa vegana | B38: 1.95
A39: Huevo | B39: 1.1 | C39: Revisar: 'Huevo' aparece dos veces con precios distintos
A40: Doble huevo | B40: 1.95
...

Sheet Suplementos Plato Combinado
A1: Nombre | B1: Precio (€) | C1: Nota
A2: Sal | C2: Sin precio en pantalla (probablemente gratis)
A3: Sin salsa brava | C3: Sin precio en pantalla (probablemente gratis)
A4: Muy hecho | C4: Sin precio en pantalla (probablemente gratis)
A5: Doble huevo | B5: 1.95
A6: Sin chistorra | C6: Sin precio en pantalla (probablemente gratis)
A7: Sin panceta | C7: Sin precio en pantalla (probablemente gratis)
A8: Sin croquetas | C8: Sin precio en pantalla (probablemente gratis)
A9: Sin lomo | C9: Sin precio en pantalla (probablemente gratis)
A10: Sin bravas | C10: Sin precio en pantalla (probablemente gratis)
A11: Con butifarra | C11: Sin precio en pantalla (probablemente gratis)
A12: Sin ensalada | C12: Sin precio en pantalla (probablemente gratis)
A13: Sin frankfurt | C13: Sin precio en pantalla (probablemente gratis)
A14: Cebolla cruda | B14: 1.05 | C14: Revisar: precio poco claro en la foto (podría ser de 'Con ensalada')
A15: Con ensalada | C15: Sin precio en pantalla (probablemente gratis)
A16: Al punto | C16: Sin precio en pantalla (probablemente gratis)
A17: Viandox | C17: Sin precio en pantalla (probablemente gratis)
A18: Con chistorra | C18: Sin precio en pantalla (probablemente gratis)
A19: Con panceta | C19: Sin precio en pantalla (probablemente gratis)
A20: Con croquetas | C20: Sin precio en pantalla (probablemente gratis)
A21: Con lomo | C21: Sin precio en pantalla (probablemente gratis)
A22: Con tortilla | C22: Sin precio en pantalla (probablemente gratis)
A23: Con frankfurt | C23: Sin precio en pantalla (probablemente gratis)
A24: Sin patatas fritas | C24: Sin precio en pantalla (probablemente gratis)
A25: Con patatas fritas | C25: Sin precio en pantalla (probablemente gratis)
A26: Frankfurt | B26: 1.75
A27: Con salchicha del país | C27: Sin precio en pantalla (probablemente gratis)
A28: Tomate del Vallès | C28: Sin precio en pantalla (probablemente gratis)
A29: Sin pikhamtwurst | C29: Sin precio en pantalla (probablemente gratis)
A30: Con bravas | C30: Sin precio en pantalla (probablemente gratis)
A31: Sin hamburguesa | C31: Sin precio en pantalla (probablemente gratis)
A32: Sin tira de pollo | C32: Sin precio en pantalla (probablemente gratis)
A33: Con huevo | B33: 1 | C33: Revisar: precio poco claro en la foto (podría ser de 'Sin calamares')
A34: Sin calamares | C34: Sin precio en pantalla (probablemente gratis)
A35: Sin butifarra | C35: Sin precio en pantalla (probablemente gratis)
A36: Sin pollo | C36: Sin precio en pantalla (probablemente gratis)
A37: Troceado | C37: Sin precio en pantalla (probablemente gratis)
A38: Doble queso | B38: 1.95
A39: Mostaza del Vallès | C39: Sin precio en pantalla (probablemente gratis)
A40: Con pikhamtwurst | C40: Sin precio en pantalla (probablemente gratis)
...

Sheet Suplementos Postres
A1: Nombre | B1: Precio (€) | C1: Nota
A2: Sin galleta | C2: Sin precio en pantalla (probablemente gratis)
A3: Sin nata | C3: Sin precio en pantalla (probablemente gratis)
A4: Sin sirope | C4: Sin precio en pantalla (probablemente gratis)
A5: Caliente | C5: Sin precio en pantalla (probablemente gratis)
A6: Sin calentar | C6: Sin precio en pantalla (probablemente gratis)

Sheet Suplementos Café
A1: Nombre | B1: Precio (€) | C1: Nota
A2: Corto de café | C2: Sin precio en pantalla (probablemente gratis)
A3: Corto de leche | C3: Sin precio en pantalla (probablemente gratis)
A4: Doble carga | B4: 0.8
A5: Limón en rodaja | B5: 0.1
A6: Para llevar | B6: 0.2
A7: Muy caliente | C7: Sin precio en pantalla (probablemente gratis)
A8: Leche natural | C8: Sin precio en pantalla (probablemente gratis)
A9: Café corto Albert | C9: Sin precio en pantalla (probablemente gratis)
A10: Hielo | B10: 0.2
A11: Con sacarina | C11: Sin precio en pantalla (probablemente gratis)
A12: Sin espuma | C12: Sin precio en pantalla (probablemente gratis)
A13: Con espuma | C13: Sin precio en pantalla (probablemente gratis)
A14: Doble hielo | B14: 0.3 | C14: Revisar: precio poco claro en la foto (podría ser de 'Con azúcar moreno')
A15: Con azúcar moreno | C15: Sin precio en pantalla (probablemente gratis)
A16: Corto | C16: Sin precio en pantalla (probablemente gratis)
A17: Largo | C17: Sin precio en pantalla (probablemente gratis)
A18: Vaso | C18: Sin precio en pantalla (probablemente gratis)
A19: Leche de avena | B19: 0.2
A20: Leche desnatada | B20: 0.2
A21: Corazón | C21: Sin precio en pantalla (probablemente gratis)

Sheet Productos
A1: Código | B1: Categoría | C1: Nombre | D1: Tarifa 1 (€) | E1: Tarifa 2 - Terraza (€) | F1: Nota
A2: 1 | B2: Bocadillos | C2: Bikini sobrasada | D2: 3.35 | E2: =IF(D2="","",D2+0.2) -> 3.55
A3: 2 | B3: Bocadillos | C3: Bikini P. país | D3: 3.35 | E3: =IF(D3="","",D3+0.2) -> 3.55 | F3: Revisar: 'P. país' en la tarifa, no sé si es pa de pagès o pernil del país
A4: 3 | B4: Bocadillos | C4: Bikini jamón dulce | D4: 3.1 | E4: =IF(D4="","",D4+0.2) -> 3.3
A5: 4 | B5: Bocadillos | C5: Bikini especial | D5: 4.5 | E5: =IF(D5="","",D5+0.2) -> 4.7
A6: 5 | B6: Bocadillos | C6: Butifarra flauta | D6: 5.95 | E6: =IF(D6="","",D6+0.2) -> 6.15
A7: 6 | B7: Bocadillos | C7: Butifarra viena | D7: 4.9 | E7: =IF(D7="","",D7+0.2) -> 5.1
A8: 7 | B8: Bocadillos | C8: Butifarra con patatas fritas | D8: 6.2 | E8: =IF(D8="","",D8+0.2) -> 6.4
A9: 8 | B9: Bocadillos | C9: Bratwurst flauta | D9: 5.15 | E9: =IF(D9="","",D9+0.2) -> 5.35
A10: 9 | B10: Bocadillos | C10: Bratwurst viena | D10: 4.55 | E10: =IF(D10="","",D10+0.2) -> 4.75
A11: 10 | B11: Bocadillos | C11: Cervela flauta | D11: 5.15 | E11: =IF(D11="","",D11+0.2) -> 5.35
A12: 11 | B12: Bocadillos | C12: Cervela viena | D12: 4.65 | E12: =IF(D12="","",D12+0.2) -> 4.85
A13: 12 | B13: Bocadillos | C13: Cansalada flauta | D13: 5.35 | E13: =IF(D13="","",D13+0.2) -> 5.55
A14: 13 | B14: Bocadillos | C14: Cansalada viena | D14: 4.55 | E14: =IF(D14="","",D14+0.2) -> 4.75
A15: 14 | B15: Bocadillos | C15: Bacon flauta | D15: 5.35 | E15: =IF(D15="","",D15+0.2) -> 5.55
... A124: 124 | B124: Cervezas | C124: Free Damm azul | D124: 2.55 | E124: =IF(D124="","",D124+0.2) -> 2.75
A125: 125 | B125: Cervezas | C125: Lúpulo tostada | D125: 2.55 | E125: =IF(D125="","",D125+0.2) -> 2.75 | F125: Revisar: en la tarifa pone 'Lupulo tostada'
A126: 126 | B126: Cervezas | C126: Free Damm amarilla | D126: 2.55 | E126: =IF(D126="","",D126+0.2) -> 2.75
A127: 127 | B127: Cervezas | C127: Tinto de verano | D127: 5.75 | E127: =IF(D127="","",D127+0.2) -> 5.95 | F127: Revisar: aparece más de una vez con precios distintos
A128: 128 | B128: Cervezas | C128: Coronita | D128: 2.7 | E128: =IF(D128="","",D128+0.2) -> 2.9
A129: 129 | B129: Cervezas | C129: Daura | D129: 2.7 | E129: =IF(D129="","",D129+0.2) -> 2.9
A130: 130 | B130: Cervezas | C130: Desperados | D130: 2.7 | E130: =IF(D130="","",D130+0.2) -> 2.9
A131: 131 | B131: Cervezas | C131: Mediana Estrella | D131: 1.95 | E131: =IF(D131="","",D131+0.2) -> 2.15
A132: 132 | B132: Cervezas | C132: Jarra para llevar | D132: 2.95 | E132: =IF(D132="","",D132+0.2) -> 3.15
A133: 133 | B133: Cervezas | C133: Quinto Free Damm tostada | D133: 1.95 | E133: =IF(D133="","",D133+0.2) -> 2.15
A134: 134 | B134: Cervezas | C134: Copa para llevar | D134: 1.5 | E134: =IF(D134="","",D134+0.2) -> 1.7
A135: 135 | B135: Cervezas | C135: Sangría de cava | D135: 12.5 | E135: =IF(D135="","",D135+0.2) -> 12.7
A136: 136 | B136: Cervezas | C136: Sangría de vino | D136: 9 | E136: =IF(D136="","",D136+0.2) -> 9.2
A137: 137 | B137: Cafés e infusiones | C137: Café solo | D137: 1.4 | E137: =IF(D137="","",D137+0.2) -> 1.6
A138: 138 | B138: Cafés e infusiones | C138: Café descafeinado | D138: 1.4 | E138: =IF(D138="","",D138+0.2) -> 1.6
A139: 139 | B139: Cafés e infusiones | C139: Café con hielo | D139: 1.6 | E139: =IF(D139="","",D139+0.2) -> 1.8
... A163: 163 | B163: Cafés e infusiones | C163: Café americano descafeinado | D163: 1.7 | E163: =IF(D163="","",D163+0.2) -> 1.9
A164: 164 | B164: Cafés e infusiones | C164: Leche desnatada | E164: =IF(D164="","",D164+0.2) | F164: Sin precio en la tarifa
A165: 165 | B165: Cafés e infusiones | C165: Capuchino | D165: 4.35 | E165: =IF(D165="","",D165+0.2) -> 4.55
A166: 166 | B166: Cafés e infusiones | C166: Café irlandés | D166: 6.5 | E166: =IF(D166="","",D166+0.2) -> 6.7
A167: 167 | B167: Cafés e infusiones | C167: Carajillo de Baileys grande | D167: 5.25 | E167: =IF(D167="","",D167+0.2) -> 5.45
A168: 168 | B168: Cafés e infusiones | C168: Trifásico de coñac | D168: 3 | E168: =IF(D168="","",D168+0.2) -> 3.2
A169: 169 | B169: Cafés e infusiones | C169: Trifásico de Baileys | D169: 3.1 | E169: =IF(D169="","",D169+0.2) -> 3.3
A170: 170 | B170: Cafés e infusiones | C170: Azúcar moreno | E170: =IF(D170="","",D170+0.2) | F170: Sin precio en la tarifa
A171: 171 | B171: Cafés e infusiones | C171: Leche de soja | E171: =IF(D171="","",D171+0.2) | F171: Sin precio en la tarifa
...

Sheet Bocadillos
A1: Código | B1: Nombre | C1: Tarifa 1 (€) | D1: Tarifa 2 - Terraza (€) | E1: Nota
A2: 1 | B2: =Productos!C2 -> Bikini sobrasada | C2: =IF(Productos!D2="","",Productos!D2) -> 3.35 | D2: =IF(Productos!E2="","",Productos!E2) -> 3.55
A3: 2 | B3: =Productos!C3 -> Bikini P. país | C3: =IF(Productos!D3="","",Productos!D3) -> 3.35 | D3: =IF(Productos!E3="","",Productos!E3) -> 3.55 | E3: Revisar: 'P. país' en la tarifa, no sé si es pa de pagès o pernil del país
A4: 3 | B4: =Productos!C4 -> Bikini jamón dulce | C4: =IF(Productos!D4="","",Productos!D4) -> 3.1 | D4: =IF(Productos!E4="","",Productos!E4) -> 3.3
A5: 4 | B5: =Productos!C5 -> Bikini especial | C5: =IF(Productos!D5="","",Productos!D5) -> 4.5 | D5: =IF(Productos!E5="","",Productos!E5) -> 4.7
A6: 5 | B6: =Productos!C6 -> Butifarra flauta | C6: =IF(Productos!D6="","",Productos!D6) -> 5.95 | D6: =IF(Productos!E6="","",Productos!E6) -> 6.15
A7: 6 | B7: =Productos!C7 -> Butifarra viena | C7: =IF(Productos!D7="","",Productos!D7) -> 4.9 | D7: =IF(Productos!E7="","",Productos!E7) -> 5.1
A8: 7 | B8: =Productos!C8 -> Butifarra con patatas fritas | C8: =IF(Productos!D8="","",Productos!D8) -> 6.2 | D8: =IF(Productos!E8="","",Productos!E8) -> 6.4
A9: 8 | B9: =Productos!C9 -> Bratwurst flauta | C9: =IF(Productos!D9="","",Productos!D9) -> 5.15 | D9: =IF(Productos!E9="","",Productos!E9) -> 5.35
A10: 9 | B10: =Productos!C10 -> Bratwurst viena | C10: =IF(Productos!D10="","",Productos!D10) -> 4.55 | D10: =IF(Productos!E10="","",Productos!E10) -> 4.75
A11: 10 | B11: =Productos!C11 -> Cervela flauta | C11: =IF(Productos!D11="","",Productos!D11) -> 5.15 | D11: =IF(Productos!E11="","",Productos!E11) -> 5.35
A12: 11 | B12: =Productos!C12 -> Cervela viena | C12: =IF(Productos!D12="","",Productos!D12) -> 4.65 | D12: =IF(Productos!E12="","",Productos!E12) -> 4.85
A13: 12 | B13: =Productos!C13 -> Cansalada flauta | C13: =IF(Productos!D13="","",Productos!D13) -> 5.35 | D13: =IF(Productos!E13="","",Productos!E13) -> 5.55
A14: 13 | B14: =Productos!C14 -> Cansalada viena | C14: =IF(Productos!D14="","",Productos!D14) -> 4.55 | D14: =IF(Productos!E14="","",Productos!E14) -> 4.75
A15: 14 | B15: =Productos!C15 -> Bacon flauta | C15: =IF(Productos!D15="","",Productos!D15) -> 5.35 | D15: =IF(Productos!E15="","",Productos!E15) -> 5.55
... A111: 111 | B111: =Productos!C111 -> Tropical viena | C111: =IF(Productos!D111="","",Productos!D111) -> 4.9 | D111: =IF(Productos!E111="","",Productos!E111) -> 5.1

Sheet Cervezas
A1: Código | B1: Nombre | C1: Tarifa 1 (€) | D1: Tarifa 2 - Terraza (€) | E1: Nota
A2: 112 | B2: =Productos!C112 -> Copa Estrella | C2: =IF(Productos!D112="","",Productos!D112) -> 2.45 | D2: =IF(Productos!E112="","",Productos!E112) -> 2.65
A3: 113 | B3: =Productos!C113 -> Jarra | C3: =IF(Productos!D113="","",Productos!D113) -> 4.8 | D3: =IF(Productos!E113="","",Productos!E113) -> 5
A4: 114 | B4: =Productos!C114 -> Zurito Estrella | C4: =IF(Productos!D114="","",Productos!D114) -> 1.75 | D4: =IF(Productos!E114="","",Productos!E114) -> 1.95
A5: 115 | B5: =Productos!C115 -> Copa clara | C5: =IF(Productos!D115="","",Productos!D115) -> 2.45 | D5: =IF(Productos!E115="","",Productos!E115) -> 2.65
A6: 116 | B6: =Productos!C116 -> Jarra clara | C6: =IF(Productos!D116="","",Productos!D116) -> 5.05 | D6: =IF(Productos!E116="","",Productos!E116) -> 5.25
A7: 117 | B7: =Productos!C117 -> Zurito clara | C7: =IF(Productos!D117="","",Productos!D117) -> 1.8 | D7: =IF(Productos!E117="","",Productos!E117) -> 2
A8: 118 | B8: =Productos!C118 -> Jarra Voll-Damm | C8: =IF(Productos!D118="","",Productos!D118) -> 5.15 | D8: =IF(Productos!E118="","",Productos!E118) -> 5.35
A9: 119 | B9: =Productos!C119 -> Voll-Damm | C9: =IF(Productos!D119="","",Productos!D119) -> 2.75 | D9: =IF(Productos!E119="","",Productos!E119) -> 2.95
A10: 120 | B10: =Productos!C120 -> Zurito Voll-Damm | C10: =IF(Productos!D120="","",Productos!D120) -> 1.8 | D10: =IF(Productos!E120="","",Productos!E120) -> 2
A11: 121 | B11: =Productos!C121 -> Zurito Turia | C11: =IF(Productos!D121="","",Productos!D121) -> 1.75 | D11: =IF(Productos!E121="","",Productos!E121) -> 1.95
A12: 122 | B12: =Productos!C122 -> Copa Turia | C12: =IF(Productos!D122="","",Productos!D122) -> 2.7 | D12: =IF(Productos!E122="","",Productos!E122) -> 2.9
A13: 123 | B13: =Productos!C123 -> Jarra Turia | C13: =IF(Productos!D123="","",Productos!D123) -> 5 | D13: =IF(Productos!E123="","",Productos!E123) -> 5.2
A14: 124 | B14: =Productos!C124 -> Free Damm azul | C14: =IF(Productos!D124="","",Productos!D124) -> 2.55 | D14: =IF(Productos!E124="","",Productos!E124) -> 2.75
A15: 125 | B15: =Productos!C125 -> Lúpulo tostada | C15: =IF(Productos!D125="","",Productos!D125) -> 2.55 | D15: =IF(Productos!E125="","",Productos!E125) -> 2.75 | E15: Revisar: en la tarifa pone 'Lupulo tostada'
A16: 126 | B16: =Productos!C126 -> Free Damm amarilla | C16: =IF(Productos!D126="","",Productos!D126) -> 2.55 | D16: =IF(Productos!E126="","",Productos!E126) -> 2.75
A17: 127 | B17: =Productos!C127 -> Tinto de verano | C17: =IF(Productos!D127="","",Productos!D127) -> 5.75 | D17: =IF(Productos!E127="","",Productos!E127) -> 5.95 | E17: Revisar: aparece más de una vez con precios distintos
A18: 128 | B18: =Productos!C128 -> Coronita | C18: =IF(Productos!D128="","",Productos!D128) -> 2.7 | D18: =IF(Productos!E128="","",Productos!E128) -> 2.9
A19: 129 | B19: =Productos!C129 -> Daura | C19: =IF(Productos!D129="","",Productos!D129) -> 2.7 | D19: =IF(Productos!E129="","",Productos!E129) -> 2.9
A20: 130 | B20: =Productos!C130 -> Desperados | C20: =IF(Productos!D130="","",Productos!D130) -> 2.7 | D20: =IF(Productos!E130="","",Productos!E130) -> 2.9
A21: 131 | B21: =Productos!C131 -> Mediana Estrella | C21: =IF(Productos!D131="","",Productos!D131) -> 1.95 | D21: =IF(Productos!E131="","",Productos!E131) -> 2.15
A22: 132 | B22: =Productos!C132 -> Jarra para llevar | C22: =IF(Productos!D132="","",Productos!D132) -> 2.95 | D22: =IF(Productos!E132="","",Productos!E132) -> 3.15
A23: 133 | B23: =Productos!C133 -> Quinto Free Damm tostada | C23: =IF(Productos!D133="","",Productos!D133) -> 1.95 | D23: =IF(Productos!E133="","",Productos!E133) -> 2.15
A24: 134 | B24: =Productos!C134 -> Copa para llevar | C24: =IF(Productos!D134="","",Productos!D134) -> 1.5 | D24: =IF(Productos!E134="","",Productos!E134) -> 1.7
A25: 135 | B25: =Productos!C135 -> Sangría de cava | C25: =IF(Productos!D135="","",Productos!D135) -> 12.5 | D25: =IF(Productos!E135="","",Productos!E135) -> 12.7
A26: 136 | B26: =Productos!C136 -> Sangría de vino | C26: =IF(Productos!D136="","",Productos!D136) -> 9 | D26: =IF(Productos!E136="","",Productos!E136) -> 9.2

Sheet Cafés e infusiones
A1: Código | B1: Nombre | C1: Tarifa 1 (€) | D1: Tarifa 2 - Terraza (€) | E1: Nota
A2: 137 | B2: =Productos!C137 -> Café solo | C2: =IF(Productos!D137="","",Productos!D137) -> 1.4 | D2: =IF(Productos!E137="","",Productos!E137) -> 1.6
A3: 138 | B3: =Productos!C138 -> Café descafeinado | C3: =IF(Productos!D138="","",Productos!D138) -> 1.4 | D3: =IF(Productos!E138="","",Productos!E138) -> 1.6
A4: 139 | B4: =Productos!C139 -> Café con hielo | C4: =IF(Productos!D139="","",Productos!D139) -> 1.6 | D4: =IF(Productos!E139="","",Productos!E139) -> 1.8
A5: 140 | B5: =Productos!C140 -> Cortado | C5: =IF(Productos!D140="","",Productos!D140) -> 1.45 | D5: =IF(Productos!E140="","",Productos!E140) -> 1.65
A6: 141 | B6: =Productos!C141 -> Cortado descafeinado | C6: =IF(Productos!D141="","",Productos!D141) -> 1.45 | D6: =IF(Productos!E141="","",Productos!E141) -> 1.65
A7: 142 | B7: =Productos!C142 -> Cortado descafeinado de sobre | C7: =IF(Productos!D142="","",Productos!D142) -> 1.45 | D7: =IF(Productos!E142="","",Productos!E142) -> 1.65
A8: 143 | B8: =Productos!C143 -> Café con leche | C8: =IF(Productos!D143="","",Productos!D143) -> 1.75 | D8: =IF(Productos!E143="","",Productos!E143) -> 1.95
A9: 144 | B9: =Productos!C144 -> Café con leche descafeinado | C9: =IF(Productos!D144="","",Productos!D144) -> 1.75 | D9: =IF(Productos!E144="","",Productos!E144) -> 1.95
A10: 145 | B10: =Productos!C145 -> Café con leche de sobre | C10: =IF(Productos!D145="","",Productos!D145) -> 1.75 | D10: =IF(Productos!E145="","",Productos!E145) -> 1.95
A11: 146 | B11: =Productos!C146 -> Carajillo de whisky | C11: =IF(Productos!D146="","",Productos!D146) -> 3 | D11: =IF(Productos!E146="","",Productos!E146) -> 3.2
A12: 147 | B12: =Productos!C147 -> Trifásico de whisky | C12: =IF(Productos!D147="","",Productos!D147) -> 3 | D12: =IF(Productos!E147="","",Productos!E147) -> 3.2
A13: 148 | B13: =Productos!C148 -> Carajillo de Anís del Mono | C13: =IF(Productos!D148="","",Productos!D148) -> 3 | D13: =IF(Productos!E148="","",Productos!E148) -> 3.2
... A28: 163 | B28: =Productos!C163 -> Café americano descafeinado | C28: =IF(Productos!D163="","",Productos!D163) -> 1.7 | D28: =IF(Productos!E163="","",Productos!E163) -> 1.9
A29: 164 | B29: =Productos!C164 -> Leche desnatada | C29: =IF(Productos!D164="","",Productos!D164) | D29: =IF(Productos!E164="","",Productos!E164) | E29: Sin precio en la tarifa
A30: 165 | B30: =Productos!C165 -> Capuchino | C30: =IF(Productos!D165="","",Productos!D165) -> 4.35 | D30: =IF(Productos!E165="","",Productos!E165) -> 4.55
A31: 166 | B31: =Productos!C166 -> Café irlandés | C31: =IF(Productos!D166="","",Productos!D166) -> 6.5 | D31: =IF(Productos!E166="","",Productos!E166) -> 6.7
A32: 167 | B32: =Productos!C167 -> Carajillo de Baileys grande | C32: =IF(Productos!D167="","",Productos!D167) -> 5.25 | D32: =IF(Productos!E167="","",Productos!E167) -> 5.45
A33: 168 | B33: =Productos!C168 -> Trifásico de coñac | C33: =IF(Productos!D168="","",Productos!D168) -> 3 | D33: =IF(Productos!E168="","",Productos!E168) -> 3.2
A34: 169 | B34: =Productos!C169 -> Trifásico de Baileys | C34: =IF(Productos!D169="","",Productos!D169) -> 3.1 | D34: =IF(Productos!E169="","",Productos!E169) -> 3.3
A35: 170 | B35: =Productos!C170 -> Azúcar moreno | C35: =IF(Productos!D170="","",Productos!D170) | D35: =IF(Productos!E170="","",Productos!E170) | E35: Sin precio en la tarifa
A36: 171 | B36: =Productos!C171 -> Leche de soja | C36: =IF(Productos!D171="","",Productos!D171) | D36: =IF(Productos!E171="","",Productos!E171) | E36: Sin precio en la tarifa
A37: 172 | B37: =Productos!C172 -> Con corazón | C37: =IF(Productos!D172="","",Productos!D172) | D37: =IF(Productos!E172="","",Productos!E172) | E37: Sin precio en la tarifa
A38: 173 | B38: =Productos!C173 -> Sacarina | C38: =IF(Productos!D173="","",Productos!D173) | D38: =IF(Productos!E173="","",Productos!E173) | E38: Sin precio en la tarifa
A39: 174 | B39: =Productos!C174 -> Vaso de leche | C39: =IF(Productos!D174="","",Productos!D174) -> 1.35 | D39: =IF(Productos!E174="","",Productos!E174) -> 1.55
A40: 175 | B40: =Productos!C175 -> Leche de avena | C40: =IF(Productos!D175="","",Productos!D175) | D40: =IF(Productos!E175="","",Productos!E175) | E40: Sin precio en la tarifa
A41: 176 | B41: =Productos!C176 -> Leche natural | C41: =IF(Productos!D176="","",Productos!D176) | D41: =IF(Productos!E176="","",Productos!E176) | E41: Sin precio en la tarifa
A42: 177 | B42: =Productos!C177 -> Café con leche XXL | C42: =IF(Productos!D177="","",Productos!D177) -> 2.2 | D42: =IF(Productos!E177="","",Productos!E177) -> 2.4

Sheet Chupitos
A1: Código | B1: Nombre | C1: Tarifa 1 (€) | D1: Tarifa 2 - Terraza (€) | E1: Nota
A2: 178 | B2: =Productos!C178 -> Chupito de hierbas | C2: =IF(Productos!D178="","",Productos!D178) -> 2.45 | D2: =IF(Productos!E178="","",Productos!E178) -> 2.65
A3: 179 | B3: =Productos!C179 -> Chupito de limoncello | C3: =IF(Productos!D179="","",Productos!D179) -> 2.45 | D3: =IF(Productos!E179="","",Productos!E179) -> 2.65
A4: 180 | B4: =Productos!C180 -> Chupito de orujo blanco | C4: =IF(Productos!D180="","",Productos!D180) -> 2.45 | D4: =IF(Productos!E180="","",Productos!E180) -> 2.65
A5: 181 | B5: =Productos!C181 -> Chupito de crema de orujo | C5: =IF(Productos!D181="","",Productos!D181) -> 2.7 | D5: =IF(Productos!E181="","",Productos!E181) -> 2.9
A6: 182 | B6: =Productos!C182 -> Chupito de orujo de café | C6: =IF(Productos!D182="","",Productos!D182) -> 2.55 | D6: =IF(Productos!E182="","",Productos!E182) -> 2.75
A7: 183 | B7: =Productos!C183 -> Chupito de Jägermeister | C7: =IF(Productos!D183="","",Productos!D183) -> 3.25 | D7: =IF(Productos!E183="","",Productos!E183) -> 3.45
A8: 184 | B8: =Productos!C184 -> Chupito de Baileys | C8: =IF(Productos!D184="","",Productos!D184) -> 2.95 | D8: =IF(Productos!E184="","",Productos!E184) -> 3.15
A9: 185 | B9: =Productos!C185 -> Grappa Nonino | C9: =IF(Productos!D185="","",Productos!D185) -> 3.5 | D9: =IF(Productos!E185="","",Productos!E185) -> 3.7
A10: 186 | B10: =Productos!C186 -> Chupito de ron Zacapa | C10: =IF(Productos!D186="","",Productos!D186) -> 3.5 | D10: =IF(Productos!E186="","",Productos!E186) -> 3.7
A11: 187 | B11: =Productos!C187 -> Chupito de whisky | C11: =IF(Productos!D187="","",Productos!D187) -> 2.75 | D11: =IF(Productos!E187="","",Productos!E187) -> 2.95
A12: 188 | B12: =Productos!C188 -> Chupito de Jack Daniel's | C12: =IF(Productos!D188="","",Productos!D188) -> 4.5 | D12: =IF(Productos!E188="","",Productos!E188) -> 4.7
A13: 189 | B13: =Productos!C189 -> Chupito de Glenrothes | C13: =IF(Productos!D189="","",Productos!D189) -> 3.75 | D13: =IF(Productos!E189="","",Productos!E189) -> 3.95
... A17: 193 | B17: =Productos!C193 -> Chupito de Cutty Sark | C17: =IF(Productos!D193="","",Productos!D193) -> 2.75 | D17: =IF(Productos!E193="","",Productos!E193) -> 2.95
A18: 194 | B18: =Productos!C194 -> Chupito de Johnnie Walker | C18: =IF(Productos!D194="","",Productos!D194) -> 7.5 | D18: =IF(Productos!E194="","",Productos!E194) -> 7.7 | E18: Revisar: aparece más de una vez con precios distintos
A19: 195 | B19: =Productos!C195 -> Chupito de Magno | C19: =IF(Productos!D195="","",Productos!D195) -> 1.95 | D19: =IF(Productos!E195="","",Productos!E195) -> 2.15
A20: 196 | B20: =Productos!C196 -> Cointreau | C20: =IF(Productos!D196="","",Productos!D196) -> 2.25 | D20: =IF(Productos!E196="","",Productos!E196) -> 2.45
A21: 197 | B21: =Productos!C197 -> Chupito de Johnnie Walker | C21: =IF(Productos!D197="","",Productos!D197) -> 3.75 | D21: =IF(Productos!E197="","",Productos!E197) -> 3.95 | E21: Revisar: aparece más de una vez con precios distintos
A22: 198 | B22: =Productos!C198 -> Chupito de Cuervo | C22: =IF(Productos!D198="","",Productos!D198) -> 2.5 | D22: =IF(Productos!E198="","",Productos!E198) -> 2.7
A23: 199 | B23: =Productos!C199 -> Chupito de tequila | C23: =IF(Productos!D199="","",Productos!D199) -> 1.95 | D23: =IF(Productos!E199="","",Productos!E199) -> 2.15
A24: 200 | B24: =Productos!C200 -> Chupito de pacharán | C24: =IF(Productos!D200="","",Productos!D200) -> 2.25 | D24: =IF(Productos!E200="","",Productos!E200) -> 2.45
A25: 201 | B25: =Productos!C201 -> Chupito | C25: =IF(Productos!D201="","",Productos!D201) -> 2.75 | D25: =IF(Productos!E201="","",Productos!E201) -> 2.95
A26: 202 | B26: =Productos!C202 -> Cubo de orujo | C26: =IF(Productos!D202="","",Productos!D202) -> 3.75 | D26: =IF(Productos!E202="","",Productos!E202) -> 3.95
A27: 203 | B27: =Productos!C203 -> Tubo de Baileys | C27: =IF(Productos!D203="","",Productos!D203) -> 6.5 | D27: =IF(Productos!E203="","",Productos!E203) -> 6.7
A28: 204 | B28: =Productos!C204 -> Tubo de orujo de hierbas | C28: =IF(Productos!D204="","",Productos!D204) -> 6 | D28: =IF(Productos!E204="","",Productos!E204) -> 6.2
A29: 205 | B29: =Productos!C205 -> Tubo de limoncello | C29: =IF(Productos!D205="","",Productos!D205) -> 5.5 | D29: =IF(Productos!E205="","",Productos!E205) -> 5.7
A30: 206 | B30: =Productos!C206 -> Tubo de crema de orujo | C30: =IF(Productos!D206="","",Productos!D206) -> 6 | D30: =IF(Productos!E206="","",Productos!E206) -> 6.2
A31: 207 | B31: =Productos!C207 -> Tubo de orujo blanco | C31: =IF(Productos!D207="","",Productos!D207) -> 5.95 | D31: =IF(Productos!E207="","",Productos!E207) -> 6.15
A32: 208 | B32: =Productos!C208 -> Tubo de pacharán | C32: =IF(Productos!D208="","",Productos!D208) -> 5.95 | D32: =IF(Productos!E208="","",Productos!E208) -> 6.15

Sheet Copas
A1: Código | B1: Nombre | C1: Tarifa 1 (€) | D1: Tarifa 2 - Terraza (€) | E1: Nota
A2: 209 | B2: =Productos!C209 -> Copa de Magno | C2: =IF(Productos!D209="","",Productos!D209) -> 2.95 | D2: =IF(Productos!E209="","",Productos!E209) -> 3.15 | E2: Revisar: aparece más de una vez con precios distintos
A3: 210 | B3: =Productos!C210 -> Veterano | C3: =IF(Productos!D210="","",Productos!D210) -> 1.7 | D3: =IF(Productos!E210="","",Productos!E210) -> 1.9
A4: 211 | B4: =Productos!C211 -> Copa de whisky J&B | C4: =IF(Productos!D211="","",Productos!D211) -> 5.5 | D4: =IF(Productos!E211="","",Productos!E211) -> 5.7
A5: 212 | B5: =Productos!C212 -> Copa de ratafía | C5: =IF(Productos!D212="","",Productos!D212) -> 3.95 | D5: =IF(Productos!E212="","",Productos!E212) -> 4.15
A6: 213 | B6: =Productos!C213 -> Copa de ron Pujol | C6: =IF(Productos!D213="","",Productos!D213) -> 3.5 | D6: =IF(Productos!E213="","",Productos!E213) -> 3.7
A7: 214 | B7: =Productos!C214 -> Tubo de Ponche Caballero | C7: =IF(Productos!D214="","",Productos!D214) -> 5.95 | D7: =IF(Productos!E214="","",Productos!E214) -> 6.15
A8: 215 | B8: =Productos!C215 -> Copa de Jack Daniel's | C8: =IF(Productos!D215="","",Productos!D215) -> 7.5 | D8: =IF(Productos!E215="","",Productos!E215) -> 7.7
A9: 216 | B9: =Productos!C216 -> Cubo de Marie Brizard | C9: =IF(Productos!D216="","",Productos!D216) -> 4.7 | D9: =IF(Productos!E216="","",Productos!E216) -> 4.9
A10: 217 | B10: =Productos!C217 -> Copa de Magno | C10: =IF(Productos!D217="","",Productos!D217) -> 3.15 | D10: =IF(Productos!E217="","",Productos!E217) -> 3.35 | E10: Revisar: aparece más de una vez con precios distintos
A11: 218 | B11: =Productos!C218 -> Copa de Anís del Mono | C11: =IF(Productos!D218="","",Productos!D218) -> 3.35 | D11: =IF(Productos!E218="","",Productos!E218) -> 3.55
A12: 219 | B12: =Productos!C219 -> Tubo de Jack Daniel's | C12: =IF(Productos!D219="","",Productos!D219) -> 7.5 | D12: =IF(Productos!E219="","",Productos!E219) -> 7.7
A13: 220 | B13: =Productos!C220 -> Tubo de Ballantine's | C13: =IF(Productos!D220="","",Productos!D220) -> 5.95 | D13: =IF(Productos!E220="","",Productos!E220) -> 6.15
A14: 221 | B14: =Productos!C221 -> Copa de Ponche Caballero | C14: =IF(Productos!D221="","",Productos!D221) -> 3.55 | D14: =IF(Productos!E221="","",Productos!E221) -> 3.75
A15: 222 | B15: =Productos!C222 -> Tubo de Anís del Mono | C15: =IF(Productos!D222="","",Productos!D222) -> 3.95 | D15: =IF(Productos!E222="","",Productos!E222) -> 4.15
A16: 223 | B16: =Productos!C223 -> Copa de Ballantine's | C16: =IF(Productos!D223="","",Productos!D223) -> 3.7 | D16: =IF(Productos!E223="","",Productos!E223) -> 3.9
A17: 224 | B17: =Productos!C224 -> Tubo de Frangelico | C17: =IF(Productos!D224="","",Productos!D224) -> 4.25 | D17: =IF(Productos!E224="","",Productos!E224) -> 4.45
A18: 225 | B18: =Productos!C225 -> Copa de Cardhu | C18: =IF(Productos!D225="","",Productos!D225) -> 8.5 | D18: =IF(Productos!E225="","",Productos!E225) -> 8.7
A19: 226 | B19: =Productos!C226 -> Copa de pacharán | C19: =IF(Productos!D226="","",Productos!D226) -> 4.5 | D19: =IF(Productos!E226="","",Productos!E226) -> 4.7
A20: 227 | B20: =Productos!C227 -> Copa de orujo de hierbas | C20: =IF(Productos!D227="","",Productos!D227) -> 4.5 | D20: =IF(Productos!E227="","",Productos!E227) -> 4.7
A21: 228 | B21: =Productos!C228 -> Copa de orujo blanco | C21: =IF(Productos!D228="","",Productos!D228) -> 3.75 | D21: =IF(Productos!E228="","",Productos!E228) -> 3.95
A22: 229 | B22: =Productos!C229 -> Copa de crema de orujo | C22: =IF(Productos!D229="","",Productos!D229) -> 3.75 | D22: =IF(Productos!E229="","",Productos!E229) -> 3.95
A23: 230 | B23: =Productos!C230 -> Copa de Baileys | C23: =IF(Productos!D230="","",Productos!D230) -> 3.75 | D23: =IF(Productos!E230="","",Productos!E230) -> 3.95
A24: 231 | B24: =Productos!C231 -> Copa de café | C24: =IF(Productos!D231="","",Productos!D231) -> 3.75 | D24: =IF(Productos!E231="","",Productos!E231) -> 3.95 | E24: Revisar: no sé si es licor de café

Sheet Cubatas
A1: Código | B1: Nombre | C1: Tarifa 1 (€) | D1: Tarifa 2 - Terraza (€) | E1: Nota
A2: 232 | B2: =Productos!C232 -> Puerto de Indias | C2: =IF(Productos!D232="","",Productos!D232) -> 7.95 | D2: =IF(Productos!E232="","",Productos!E232) -> 8.15
A3: 233 | B3: =Productos!C233 -> Bombay | C3: =IF(Productos!D233="","",Productos!D233) -> 8.5 | D3: =IF(Productos!E233="","",Productos!E233) -> 8.7
A4: 234 | B4: =Productos!C234 -> Bacardí | C4: =IF(Productos!D234="","",Productos!D234) -> 7.8 | D4: =IF(Productos!E234="","",Productos!E234) -> 8
A5: 235 | B5: =Productos!C235 -> Brugal | C5: =IF(Productos!D235="","",Productos!D235) -> 7.8 | D5: =IF(Productos!E235="","",Productos!E235) -> 8
A6: 236 | B6: =Productos!C236 -> Cacique | C6: =IF(Productos!D236="","",Productos!D236) -> 7.75 | D6: =IF(Productos!E236="","",Productos!E236) -> 7.95
A7: 237 | B7: =Productos!C237 -> Cubata Cutty Sark | C7: =IF(Productos!D237="","",Productos!D237) -> 7.7 | D7: =IF(Productos!E237="","",Productos!E237) -> 7.9
A8: 238 | B8: =Productos!C238 -> Cubata J&B | C8: =IF(Productos!D238="","",Productos!D238) -> 7.7 | D8: =IF(Productos!E238="","",Productos!E238) -> 7.9
A9: 239 | B9: =Productos!C239 -> Cubata Ballantine's | C9: =IF(Productos!D239="","",Productos!D239) -> 7.7 | D9: =IF(Productos!E239="","",Productos!E239) -> 7.9
A10: 240 | B10: =Productos!C240 -> Vodka | C10: =IF(Productos!D240="","",Productos!D240) -> 7.7 | D10: =IF(Productos!E240="","",Productos!E240) -> 7.9
A11: 241 | B11: =Productos!C241 -> Jack Daniel's | C11: =IF(Productos!D241="","",Productos!D241) -> 8.5 | D11: =IF(Productos!E241="","",Productos!E241) -> 8.7
A12: 242 | B12: =Productos!C242 -> Mojito | C12: =IF(Productos!D242="","",Productos!D242) -> 6.95 | D12: =IF(Productos!E242="","",Productos!E242) -> 7.15
A13: 243 | B13: =Productos!C243 -> Beefeater | C13: =IF(Productos!D243="","",Productos!D243) -> 7.7 | D13: =IF(Productos!E243="","",Productos!E243) -> 7.9
... A15: 245 | B15: =Productos!C245 -> Four Roses | C15: =IF(Productos!D245="","",Productos!D245) -> 6.5 | D15: =IF(Productos!E245="","",Productos!E245) -> 6.7

Sheet Ensaladas, menús y combinados
A1: Código | B1: Nombre | C1: Tarifa 1 (€) | D1: Tarifa 2 - Terraza (€) | E1: Nota
A2: 246 | B2: =Productos!C246 -> Ensalada de pollo | C2: =IF(Productos!D246="","",Productos!D246) -> 5.5 | D2: =IF(Productos!E246="","",Productos!E246) -> 5.7
A3: 247 | B3: =Productos!C247 -> Ensalada de queso | C3: =IF(Productos!D247="","",Productos!D247) -> 7.5 | D3: =IF(Productos!E247="","",Productos!E247) -> 7.7
A4: 248 | B4: =Productos!C248 -> Ensalada verde | C4: =IF(Productos!D248="","",Productos!D248) -> 5.7 | D4: =IF(Productos!E248="","",Productos!E248) -> 5.9
A5: 249 | B5: =Productos!C249 -> Ensalada Els Tr3s | C5: =IF(Productos!D249="","",Productos!D249) -> 7.95 | D5: =IF(Productos!E249="","",Productos!E249) -> 8.15
A6: 250 | B6: =Productos!C250 -> Menú especial | C6: =IF(Productos!D250="","",Productos!D250) -> 13.5 | D6: =IF(Productos!E250="","",Productos!E250) -> 13.7
A7: 251 | B7: =Productos!C251 -> Menú | C7: =IF(Productos!D251="","",Productos!D251) -> 9.95 | D7: =IF(Productos!E251="","",Productos!E251) -> 10.15
A8: 252 | B8: =Productos!C252 -> Sepia a la plancha con guarnición | C8: =IF(Productos!D252="","",Productos!D252) -> 10.25 | D8: =IF(Productos!E252="","",Productos!E252) -> 10.45
A9: 253 | B9: =Productos!C253 -> Entrecot con guarnición | C9: =IF(Productos!D253="","",Productos!D253) -> 13.95 | D9: =IF(Productos!E253="","",Productos!E253) -> 14.15
A10: 254 | B10: =Productos!C254 -> Paella | C10: =IF(Productos!D254="","",Productos!D254) -> 6.5 | D10: =IF(Productos!E254="","",Productos!E254) -> 6.7
A11: 255 | B11: =Productos!C255 -> Menú Uri | C11: =IF(Productos!D255="","",Productos!D255) -> 10 | D11: =IF(Productos!E255="","",Productos!E255) -> 10.2
A12: 256 | B12: =Productos!C256 -> Fideuá | C12: =IF(Productos!D256="","",Productos!D256) -> 5.5 | D12: =IF(Productos!E256="","",Productos!E256) -> 5.7
A13: 257 | B13: =Productos!C257 -> Amanida braves butifarra | C13: =IF(Productos!D257="","",Productos!D257) -> 12.5 | D13: =IF(Productos!E257="","",Productos!E257) -> 12.7
... A28: 272 | B28: =Productos!C272 -> Menú IO | C28: =IF(Productos!D272="","",Productos!D272) -> 5.75 | D28: =IF(Productos!E272="","",Productos!E272) -> 5.95

Sheet Postres
A1: Código | B1: Nombre | C1: Tarifa 1 (€) | D1: Tarifa 2 - Terraza (€) | E1: Nota
A2: 273 | B2: =Productos!C273 -> Tarta de whisky | C2: =IF(Productos!D273="","",Productos!D273) -> 4.55 | D2: =IF(Productos!E273="","",Productos!E273) -> 4.75
A3: 274 | B3: =Productos!C274 -> Tarta dulce | C3: =IF(Productos!D274="","",Productos!D274) -> 4.55 | D3: =IF(Productos!E274="","",Productos!E274) -> 4.75
A4: 275 | B4: =Productos!C275 -> Naranja o plátano | C4: =IF(Productos!D275="","",Productos!D275) -> 3.5 | D4: =IF(Productos!E275="","",Productos!E275) -> 3.7
A5: 276 | B5: =Productos!C276 -> Tarta de queso | C5: =IF(Productos!D276="","",Productos!D276) -> 4.95 | D5: =IF(Productos!E276="","",Productos!E276) -> 5.15
A6: 277 | B6: =Productos!C277 -> Arroz con leche | C6: =IF(Productos!D277="","",Productos!D277) -> 3.25 | D6: =IF(Productos!E277="","",Productos!E277) -> 3.45
A7: 278 | B7: =Productos!C278 -> Yogur | C7: =IF(Productos!D278="","",Productos!D278) -> 1.95 | D7: =IF(Productos!E278="","",Productos!E278) -> 2.15
A8: 279 | B8: =Productos!C279 -> Tarta brownie | C8: =IF(Productos!D279="","",Productos!D279) -> 3.55 | D8: =IF(Productos!E279="","",Productos!E279) -> 3.75
A9: 280 | B9: =Productos!C280 -> Helado de la casa | C9: =IF(Productos!D280="","",Productos!D280) -> 4.55 | D9: =IF(Productos!E280="","",Productos!E280) -> 4.75
A10: 281 | B10: =Productos!C281 -> Flan | C10: =IF(Productos!D281="","",Productos!D281) -> 3.45 | D10: =IF(Productos!E281="","",Productos!E281) -> 3.65
A11: 282 | B11: =Productos!C282 -> Coulant de chocolate | C11: =IF(Productos!D282="","",Productos!D282) -> 3.55 | D11: =IF(Productos!E282="","",Productos!E282) -> 3.75
A12: 283 | B12: =Productos!C283 -> Tarta de zanahoria | C12: =IF(Productos!D283="","",Productos!D283) -> 4.75 | D12: =IF(Productos!E283="","",Productos!E283) -> 4.95
A13: 285 | B13: =Productos!C284 -> Cornetto de chocolate | C13: =IF(Productos!D284="","",Productos!D284) -> 2.95 | D13: =IF(Productos!E284="","",Productos!E284) -> 3.15
A14: 287 | B14: =Productos!C285 -> Almendrado | C14: =IF(Productos!D285="","",Productos!D285) -> 3.25 | D14: =IF(Productos!E285="","",Productos!E285) -> 3.45

Sheet Refrescos
A1: Código | B1: Nombre | C1: Tarifa 1 (€) | D1: Tarifa 2 - Terraza (€) | E1: Nota
A2: 288 | B2: =Productos!C286 -> Coca-Cola | C2: =IF(Productos!D286="","",Productos!D286) -> 2.35 | D2: =IF(Productos!E286="","",Productos!E286) -> 2.55
A3: 289 | B3: =Productos!C287 -> Fanta naranja | C3: =IF(Productos!D287="","",Productos!D287) -> 2.35 | D3: =IF(Productos!E287="","",Productos!E287) -> 2.55
A4: 290 | B4: =Productos!C288 -> Fanta limón | C4: =IF(Productos!D288="","",Productos!D288) -> 2.35 | D4: =IF(Productos!E288="","",Productos!E288) -> 2.55
A5: 291 | B5: =Productos!C289 -> Aquarius | C5: =IF(Productos!D289="","",Productos!D289) -> 2.35 | D5: =IF(Productos!E289="","",Productos!E289) -> 2.55
A6: 292 | B6: =Productos!C290 -> Tónica | C6: =IF(Productos!D290="","",Productos!D290) -> 2.35 | D6: =IF(Productos!E290="","",Productos!E290) -> 2.55
A7: 293 | B7: =Productos!C291 -> Trina limón | C7: =IF(Productos!D291="","",Productos!D291) -> 2.35 | D7: =IF(Productos!E291="","",Productos!E291) -> 2.55
A8: 294 | B8: =Productos!C292 -> Aquarius naranja | C8: =IF(Productos!D292="","",Productos!D292) -> 2.35 | D8: =IF(Productos!E292="","",Productos!E292) -> 2.55 | E8: Revisar: aparece más de una vez con precios distintos
A9: 295 | B9: =Productos!C293 -> Vichy Catalán | C9: =IF(Productos!D293="","",Productos!D293) -> 2.35 | D9: =IF(Productos!E293="","",Productos!E293) -> 2.55
A10: 296 | B10: =Productos!C294 -> Zumo de melocotón | C10: =IF(Productos!D294="","",Productos!D294) -> 2.35 | D10: =IF(Productos!E294="","",Productos!E294) -> 2.55
A11: 297 | B11: =Productos!C295 -> Zumo de naranja | C11: =IF(Productos!D295="","",Productos!D295) -> 2.35 | D11: =IF(Productos!E295="","",Productos!E295) -> 2.55
A12: 298 | B12: =Productos!C296 -> Zumo de naranja natural | C12: =IF(Productos!D296="","",Productos!D296) -> 3.15 | D12: =IF(Productos!E296="","",Productos!E296) -> 3.35
A13: 299 | B13: =Productos!C297 -> Zumo de piña | C13: =IF(Productos!D297="","",Productos!D297) -> 2.35 | D13: =IF(Productos!E297="","",Productos!E297) -> 2.55
A14: 300 | B14: =Productos!C298 -> Coca-Cola Zero | C14: =IF(Productos!D298="","",Productos!D298) -> 2.35 | D14: =IF(Productos!E298="","",Productos!E298) -> 2.55
A15: 301 | B15: =Productos!C299 -> Cacaolat | C15: =IF(Productos!D299="","",Productos!D299) -> 2.35 | D15: =IF(Productos!E299="","",Productos!E299) -> 2.55
A16: 302 | B16: =Productos!C300 -> Red Bull | C16: =IF(Productos!D300="","",Productos!D300) -> 2.95 | D16: =IF(Productos!E300="","",Productos!E300) -> 3.15
A17: 303 | B17: =Productos!C301 -> Bolsa | C17: =IF(Productos!D301="","",Productos!D301) -> 0.15 | D17: =IF(Productos!E301="","",Productos!E301) -> 0.35
A18: 304 | B18: =Productos!C302 -> Bitter Kas | C18: =IF(Productos!D302="","",Productos!D302) -> 2.35 | D18: =IF(Productos!E302="","",Productos!E302) -> 2.55
A19: 305 | B19: =Productos!C303 -> Agua 1 L | C19: =IF(Productos!D303="","",Productos!D303) -> 2.55 | D19: =IF(Productos!E303="","",Productos!E303) -> 2.75
A20: 306 | B20: =Productos!C304 -> Agua 1/2 L | C20: =IF(Productos!D304="","",Productos!D304) -> 1.45 | D20: =IF(Productos!E304="","",Productos!E304) -> 1.65
... A23: 309 | B23: =Productos!C307 -> Nestea | C23: =IF(Productos!D307="","",Productos!D307) -> 2.35 | D23: =IF(Productos!E307="","",Productos!E307) -> 2.55
A24: 310 | B24: =Productos!C308 -> Sin limón | C24: =IF(Productos!D308="","",Productos!D308) | D24: =IF(Productos!E308="","",Productos!E308) | E24: Sin precio en la tarifa
A25: 311 | B25: =Productos!C309 -> Sin hielo | C25: =IF(Productos!D309="","",Productos!D309) | D25: =IF(Productos!E309="","",Productos!E309) | E25: Sin precio en la tarifa
A26: 312 | B26: =Productos!C310 -> Vaso | C26: =IF(Productos!D310="","",Productos!D310) | D26: =IF(Productos!E310="","",Productos!E310) | E26: Sin precio en la tarifa
A27: 313 | B27: =Productos!C311 -> Hielo | C27: =IF(Productos!D311="","",Productos!D311) | D27: =IF(Productos!E311="","",Productos!E311) | E27: Sin precio en la tarifa
A28: 314 | B28: =Productos!C312 -> Agua grande | C28: =IF(Productos!D312="","",Productos!D312) -> 2.05 | D28: =IF(Productos!E312="","",Productos!E312) -> 2.25
A29: 315 | B29: =Productos!C313 -> Coca-Cola 200 ml | C29: =IF(Productos!D313="","",Productos!D313) -> 2.35 | D29: =IF(Productos!E313="","",Productos!E313) -> 2.55
A30: 316 | B30: =Productos!C314 -> Coca-Cola Light | C30: =IF(Productos!D314="","",Productos!D314) -> 2.05 | D30: =IF(Productos!E314="","",Productos!E314) -> 2.25
A31: 317 | B31: =Productos!C315 -> Cola Cao | C31: =IF(Productos!D315="","",Productos!D315) -> 2.6 | D31: =IF(Productos!E315="","",Productos!E315) -> 2.8
A32: 318 | B32: =Productos!C316 -> Agua natural pequeña | C32: =IF(Productos!D316="","",Productos!D316) -> 1.45 | D32: =IF(Productos!E316="","",Productos!E316) -> 1.65
A33: 319 | B33: =Productos!C317 -> Mucho hielo | C33: =IF(Productos!D317="","",Productos!D317) -> 0.35 | D33: =IF(Productos!E317="","",Productos!E317) -> 0.55
A34: 320 | B34: =Productos!C318 -> Caliente | C34: =IF(Productos!D318="","",Productos!D318) -> 0.1 | D34: =IF(Productos!E318="","",Productos!E318) -> 0.3
A35: 321 | B35: =Productos!C319 -> Olivas de la casa | C35: =IF(Productos!D319="","",Productos!D319) -> 0.1 | D35: =IF(Productos!E319="","",Productos!E319) -> 0.3
A36: 322 | B36: =Productos!C320 -> Kikos de la casa | C36: =IF(Productos!D320="","",Productos!D320) -> 0.1 | D36: =IF(Productos!E320="","",Productos!E320) -> 0.3
A37: 323 | B37: =Productos!C321 -> Aquarius naranja | C37: =IF(Productos!D321="","",Productos!D321) -> 2.05 | D37: =IF(Productos!E321="","",Productos!E321) -> 2.25 | E37: Revisar: aparece más de una vez con precios distintos

Sheet Tapas
A1: Código | B1: Nombre | C1: Tarifa 1 (€) | D1: Tarifa 2 - Terraza (€) | E1: Nota
A2: 324 | B2: =Productos!C322 -> Bravas bravas bravas | C2: =IF(Productos!D322="","",Productos!D322) -> 6.7 | D2: =IF(Productos!E322="","",Productos!E322) -> 6.9
A3: 325 | B3: =Productos!C323 -> Tapa de chocos | C3: =IF(Productos!D323="","",Productos!D323) -> 11.5 | D3: =IF(Productos!E323="","",Productos!E323) -> 11.7
A4: 326 | B4: =Productos!C324 -> Berenjena | C4: =IF(Productos!D324="","",Productos!D324) -> 7.95 | D4: =IF(Productos!E324="","",Productos!E324) -> 8.15
A5: 327 | B5: =Productos!C325 -> Tapa de puntillas | C5: =IF(Productos!D325="","",Productos!D325) -> 11.5 | D5: =IF(Productos!E325="","",Productos!E325) -> 11.7
A6: 328 | B6: =Productos!C326 -> Tapa de pinchos | C6: =IF(Productos!D326="","",Productos!D326) -> 9.7 | D6: =IF(Productos!E326="","",Productos!E326) -> 9.9
A7: 329 | B7: =Productos!C327 -> Tapa de patatas fritas | C7: =IF(Productos!D327="","",Productos!D327) -> 3.9 | D7: =IF(Productos!E327="","",Productos!E327) -> 4.1
A8: 330 | B8: =Productos!C328 -> Tapa de croquetas | C8: =IF(Productos!D328="","",Productos!D328) -> 7.6 | D8: =IF(Productos!E328="","",Productos!E328) -> 7.8
A9: 331 | B9: =Productos!C329 -> Nuggets | C9: =IF(Productos!D329="","",Productos!D329) -> 7.5 | D9: =IF(Productos!E329="","",Productos!E329) -> 7.7
A10: 332 | B10: =Productos!C330 -> Limón | C10: =IF(Productos!D330="","",Productos!D330) | D10: =IF(Productos!E330="","",Productos!E330) | E10: Sin precio en la tarifa
A11: 333 | B11: =Productos!C331 -> Tapa de calamares a la andaluza | C11: =IF(Productos!D331="","",Productos!D331) -> 8.5 | D11: =IF(Productos!E331="","",Productos!E331) -> 8.7
A12: 334 | B12: =Productos!C332 -> Tapa de alitas de pollo | C12: =IF(Productos!D332="","",Productos!D332) -> 7.95 | D12: =IF(Productos!E332="","",Productos!E332) -> 8.15
A13: 335 | B13: =Productos!C333 -> Alcachofas chips | C13: =IF(Productos!D333="","",Productos!D333) -> 9.7 | D13: =IF(Productos!E333="","",Productos!E333) -> 9.9
A14: 336 | B14: =Productos!C334 -> Rodaja con tomate | C14: =IF(Productos!D334="","",Productos!D334) -> 1.95 | D14: =IF(Productos!E334="","",Productos!E334) -> 2.15
A15: 337 | B15: =Productos!C335 -> Tapa de tiras de pollo | C15: =IF(Productos!D335="","",Productos!D335) -> 8.35 | D15: =IF(Productos!E335="","",Productos!E335) -> 8.55
A16: 338 | B16: =Productos!C336 -> Rabas de calamar | C16: =IF(Productos!D336="","",Productos!D336) -> 6.95 | D16: =IF(Productos!E336="","",Productos!E336) -> 7.15
A17: 339 | B17: =Productos!C337 -> Tenedor tapas | C17: =IF(Productos!D337="","",Productos!D337) | D17: =IF(Productos!E337="","",Productos!E337) | E17: Sin precio en la tarifa
A18: 340 | B18: =Productos!C338 -> Ensaladilla rusa | C18: =IF(Productos!D338="","",Productos!D338) -> 4.75 | D18: =IF(Productos!E338="","",Productos!E338) -> 4.95
A19: 341 | B19: =Productos!C339 -> Albóndigas en salsa | C19: =IF(Productos!D339="","",Productos!D339) -> 4.25 | D19: =IF(Productos!E339="","",Productos!E339) -> 4.45
A20: 342 | B20: =Productos!C340 -> Tortilla de patata con cebolla | C20: =IF(Productos!D340="","",Productos!D340) -> 9.5 | D20: =IF(Productos!E340="","",Productos!E340) -> 9.7
A21: 343 | B21: =Productos!C341 -> Patata bomba | C21: =IF(Productos!D341="","",Productos!D341) -> 4.35 | D21: =IF(Productos!E341="","",Productos!E341) -> 4.55
A22: 344 | B22: =Productos!C342 -> Media de bravas | C22: =IF(Productos!D342="","",Productos!D342) -> 3.95 | D22: =IF(Productos!E342="","",Productos!E342) -> 4.15
A23: 345 | B23: =Productos!C343 -> Media de chocos | C23: =IF(Productos!D343="","",Productos!D343) -> 5 | D23: =IF(Productos!E343="","",Productos!E343) -> 5.2
A24: 346 | B24: =Productos!C344 -> Rodaja de pan | C24: =IF(Productos!D344="","",Productos!D344) -> 1.35 | D24: =IF(Productos!E344="","",Productos!E344) -> 1.55
A25: 347 | B25: =Productos!C345 -> Pulpo Els Tr3s | C25: =IF(Productos!D345="","",Productos!D345) -> 15 | D25: =IF(Productos!E345="","",Productos!E345) -> 15.2
A26: 348 | B26: =Productos!C346 -> Huevo al plato | C26: =IF(Productos!D346="","",Productos!D346) -> 1.5 | D26: =IF(Productos!E346="","",Productos!E346) -> 1.7
A27: 349 | B27: =Productos!C347 -> Tapa de queso semicurado | C27: =IF(Productos!D347="","",Productos!D347) -> 5.25 | D27: =IF(Productos!E347="","",Productos!E347) -> 5.45
A28: 350 | B28: =Productos!C348 -> Escupiñas | C28: =IF(Productos!D348="","",Productos!D348) -> 9.85 | D28: =IF(Productos!E348="","",Productos!E348) -> 10.05
A29: 351 | B29: =Productos!C349 -> Anchoas de L'Escala | C29: =IF(Productos!D349="","",Productos!D349) -> 7.25 | D29: =IF(Productos!E349="","",Productos!E349) -> 7.45
A30: 352 | B30: =Productos!C350 -> Boquerones en vinagre | C30: =IF(Productos!D350="","",Productos!D350) -> 7.25 | D30: =IF(Productos!E350="","",Productos!E350) -> 7.45
A31: 353 | B31: =Productos!C351 -> Tapa de mejillones en escabeche | C31: =IF(Productos!D351="","",Productos!D351) | D31: =IF(Productos!E351="","",Productos!E351) | E31: Sin precio en la tarifa
A32: 354 | B32: =Productos!C352 -> Longaniza (tapa) | C32: =IF(Productos!D352="","",Productos!D352) -> 5.5 | D32: =IF(Productos!E352="","",Productos!E352) -> 5.7
A33: 355 | B33: =Productos!C353 -> Olivas rellenas | C33: =IF(Productos!D353="","",Productos!D353) -> 2.95 | D33: =IF(Productos!E353="","",Productos!E353) -> 3.15
A34: 356 | B34: =Productos!C354 -> Patatas chips | C34: =IF(Productos!D354="","",Productos!D354) -> 1.55 | D34: =IF(Productos!E354="","",Productos!E354) -> 1.75
A35: 357 | B35: =Productos!C355 -> Tapa de queso manchego | C35: =IF(Productos!D355="","",Productos!D355) -> 7.75 | D35: =IF(Productos!E355="","",Productos!E355) -> 7.95
A36: 358 | B36: =Productos!C356 -> Jamón serrano (tapa) | C36: =IF(Productos!D356="","",Productos!D356) -> 6.5 | D36: =IF(Productos!E356="","",Productos!E356) -> 6.7
A37: 359 | B37: =Productos!C357 -> Tapa de jamón ibérico | C37: =IF(Productos!D357="","",Productos!D357) -> 12.5 | D37: =IF(Productos!E357="","",Productos!E357) -> 12.7

Sheet Torradas
A1: Código | B1: Nombre | C1: Tarifa 1 (€) | D1: Tarifa 2 - Terraza (€) | E1: Nota
A2: 360 | B2: =Productos!C358 -> Torrada sobrasada, formatge i ou de guatlla (1) | C2: =IF(Productos!D358="","",Productos!D358) -> 6.95 | D2: =IF(Productos!E358="","",Productos!E358) -> 7.15
A3: 361 | B3: =Productos!C359 -> Torrada cansalada, xistorra, ou i formatge (2) | C3: =IF(Productos!D359="","",Productos!D359) -> 7.95 | D3: =IF(Productos!E359="","",Productos!E359) -> 8.15
A4: 362 | B4: =Productos!C360 -> Torrada pollastre, xampinyons, ou, ceba i formatge (3) | C4: =IF(Productos!D360="","",Productos!D360) -> 7.95 | D4: =IF(Productos!E360="","",Productos!E360) -> 8.15
A5: 363 | B5: =Productos!C361 -> Torrada vedella, xampinyons, ceba i formatge (4) | C5: =IF(Productos!D361="","",Productos!D361) -> 7.15 | D5: =IF(Productos!E361="","",Productos!E361) -> 7.35
A6: 364 | B6: =Productos!C362 -> Torrada de llom (5) | C6: =IF(Productos!D362="","",Productos!D362) -> 5.5 | D6: =IF(Productos!E362="","",Productos!E362) -> 5.7
A7: 365 | B7: =Productos!C363 -> Torrada de pollastre (6) | C7: =IF(Productos!D363="","",Productos!D363) -> 5.95 | D7: =IF(Productos!E363="","",Productos!E363) -> 6.15
A8: 366 | B8: =Productos!C364 -> Torrada de truita francesa | C8: =IF(Productos!D364="","",Productos!D364) -> 4.6 | D8: =IF(Productos!E364="","",Productos!E364) -> 4.8
A9: 367 | B9: =Productos!C365 -> Torrada d'escalivada i anxova | C9: =IF(Productos!D365="","",Productos!D365) -> 7.6 | D9: =IF(Productos!E365="","",Productos!E365) -> 7.8
A10: 368 | B10: =Productos!C366 -> Torrada de pinxo | C10: =IF(Productos!D366="","",Productos!D366) -> 6.6 | D10: =IF(Productos!E366="","",Productos!E366) -> 6.8
A11: 369 | B11: =Productos!C367 -> Torrada de botifarra | C11: =IF(Productos!D367="","",Productos!D367) -> 5.6 | D11: =IF(Productos!E367="","",Productos!E367) -> 5.8
A12: 370 | B12: =Productos!C368 -> Torrada de llonganissa | C12: =IF(Productos!D368="","",Productos!D368) -> 6.75 | D12: =IF(Productos!E368="","",Productos!E368) -> 6.95
A13: 371 | B13: =Productos!C369 -> Escalivada de pebrot vermell i albergínia | C13: =IF(Productos!D369="","",Productos!D369) -> 9.85 | D13: =IF(Productos!E369="","",Productos!E369) -> 10.05
... A20: 378 | B20: =Productos!C376 -> Torrada de formatge semicurat | C20: =IF(Productos!D376="","",Productos!D376) -> 7.5 | D20: =IF(Productos!E376="","",Productos!E376) -> 7.7

Sheet Vinos
A1: Código | B1: Nombre | C1: Tarifa 1 (€) | D1: Tarifa 2 - Terraza (€) | E1: Nota
A2: 379 | B2: =Productos!C377 -> Ampolla de vi blanc | C2: =IF(Productos!D377="","",Productos!D377) -> 13.5 | D2: =IF(Productos!E377="","",Productos!E377) -> 13.7
A3: 380 | B3: =Productos!C378 -> Ampolla de vi negre | C3: =IF(Productos!D378="","",Productos!D378) -> 12.5 | D3: =IF(Productos!E378="","",Productos!E378) -> 12.7
A4: 381 | B4: =Productos!C379 -> Ampolla de vi rosat | C4: =IF(Productos!D379="","",Productos!D379) -> 12.5 | D4: =IF(Productos!E379="","",Productos!E379) -> 12.7
A5: 382 | B5: =Productos!C380 -> Azabache | C5: =IF(Productos!D380="","",Productos!D380) -> 12.5 | D5: =IF(Productos!E380="","",Productos!E380) -> 12.7
A6: 383 | B6: =Productos!C381 -> Sangría de vino | C6: =IF(Productos!D381="","",Productos!D381) -> 9 | D6: =IF(Productos!E381="","",Productos!E381) -> 9.2
A7: 384 | B7: =Productos!C382 -> Sangría de cava | C7: =IF(Productos!D382="","",Productos!D382) -> 12.5 | D7: =IF(Productos!E382="","",Productos!E382) -> 12.7
A8: 385 | B8: =Productos!C383 -> Tinto de verano | C8: =IF(Productos!D383="","",Productos!D383) -> 5.65 | D8: =IF(Productos!E383="","",Productos!E383) -> 5.85 | E8: Revisar: aparece más de una vez con precios distintos
A9: 386 | B9: =Productos!C384 -> Martini blanco | C9: =IF(Productos!D384="","",Productos!D384) -> 4.75 | D9: =IF(Productos!E384="","",Productos!E384) -> 4.95
A10: 387 | B10: =Productos!C385 -> Martini rojo | C10: =IF(Productos!D385="","",Productos!D385) -> 4.75 | D10: =IF(Productos!E385="","",Productos!E385) -> 4.95
A11: 388 | B11: =Productos!C386 -> Copa de vino tinto | C11: =IF(Productos!D386="","",Productos!D386) -> 3.05 | D11: =IF(Productos!E386="","",Productos!E386) -> 3.25
A12: 389 | B12: =Productos!C387 -> Copa de vino blanco | C12: =IF(Productos!D387="","",Productos!D387) -> 3.05 | D12: =IF(Productos!E387="","",Productos!E387) -> 3.25
A13: 390 | B13: =Productos!C388 -> Copa de vino rosado | C13: =IF(Productos!D388="","",Productos!D388) -> 3.05 | D13: =IF(Productos!E388="","",Productos!E388) -> 3.25
A14: 391 | B14: =Productos!C389 -> Vermut casero | C14: =IF(Productos!D389="","",Productos!D389) -> 3.95 | D14: =IF(Productos!E389="","",Productos!E389) -> 4.15
A15: 392 | B15: =Productos!C390 -> Chispazo | C15: =IF(Productos!D390="","",Productos!D390) -> 4.95 | D15: =IF(Productos!E390="","",Productos!E390) -> 5.15
A16: 393 | B16: =Productos!C391 -> Vermut blanco o rojo | C16: =IF(Productos!D391="","",Productos!D391) -> 5.5 | D16: =IF(Productos!E391="","",Productos!E391) -> 5.7

Sheet Desayunos
A1: Código | B1: Nombre | C1: Tarifa 1 (€) | D1: Tarifa 2 - Terraza (€) | E1: Nota
A2: 394 | B2: =Productos!C392 -> Cruasán | C2: =IF(Productos!D392="","",Productos!D392) -> 1.85 | D2: =IF(Productos!E392="","",Productos!E392) -> 2.05
A3: 395 | B3: =Productos!C393 -> Cruasán de chocolate | C3: =IF(Productos!D393="","",Productos!D393) -> 1.95 | D3: =IF(Productos!E393="","",Productos!E393) -> 2.15
A4: 396 | B4: =Productos!C394 -> Buñuelo | C4: =IF(Productos!D394="","",Productos!D394) -> 0.35 | D4: =IF(Productos!E394="","",Productos!E394) -> 0.55
A5: 397 | B5: =Productos!C395 -> Bollería especial | C5: =IF(Productos!D395="","",Productos!D395) -> 2.3 | D5: =IF(Productos!E395="","",Productos!E395) -> 2.5
A6: 398 | B6: =Productos!C396 -> Mini cruasán | C6: =IF(Productos!D396="","",Productos!D396) -> 0.65 | D6: =IF(Productos!E396="","",Productos!E396) -> 0.85
A7: 399 | B7: =Productos!C397 -> Llesca de pan con mermelada | C7: =IF(Productos!D397="","",Productos!D397) -> 1.95 | D7: =IF(Productos!E397="","",Productos!E397) -> 2.15
A8: 400 | B8: =Productos!C398 -> Mini de jamón dulce | C8: =IF(Productos!D398="","",Productos!D398) -> 2.55 | D8: =IF(Productos!E398="","",Productos!E398) -> 2.75
A9: 401 | B9: =Productos!C399 -> Mini de jamón salado | C9: =IF(Productos!D399="","",Productos!D399) -> 2.85 | D9: =IF(Productos!E399="","",Productos!E399) -> 3.05
A10: 402 | B10: =Productos!C400 -> Mini de queso | C10: =IF(Productos!D400="","",Productos!D400) -> 3 | D10: =IF(Productos!E400="","",Productos!E400) -> 3.2
A11: 403 | B11: =Productos!C401 -> Mini de queso manchego | C11: =IF(Productos!D401="","",Productos!D401) -> 3.05 | D11: =IF(Productos!E401="","",Productos!E401) -> 3.25
A12: 404 | B12: =Productos!C402 -> Mini de fuet | C12: =IF(Productos!D402="","",Productos!D402) -> 2.85 | D12: =IF(Productos!E402="","",Productos!E402) -> 3.05
A13: 405 | B13: =Productos!C403 -> Mini de tortilla | C13: =IF(Productos!D403="","",Productos!D403) -> 2.85 | D13: =IF(Productos!E403="","",Productos!E403) -> 3.05
A14: 406 | B14: =Productos!C404 -> Mini de atún | C14: =IF(Productos!D404="","",Productos!D404) -> 2.65 | D14: =IF(Productos!E404="","",Productos!E404) -> 2.85
A15: 407 | B15: =Productos!C405 -> Mini vegetal | C15: =IF(Productos!D405="","",Productos!D405) -> 2.6 | D15: =IF(Productos!E405="","",Productos!E405) -> 2.8 | E15: Revisar: aparece más de una vez con precios distintos
A16: 408 | B16: =Productos!C406 -> Tostada con mantequilla | C16: =IF(Productos!D406="","",Productos!D406) -> 1.95 | D16: =IF(Productos!E406="","",Productos!E406) -> 2.15
A17: 409 | B17: =Productos!C407 -> Mini + café | C17: =IF(Productos!D407="","",Productos!D407) -> 3.15 | D17: =IF(Productos!E407="","",Productos!E407) -> 3.35
A18: 410 | B18: =Productos!C408 -> Tostada con aceite | C18: =IF(Productos!D408="","",Productos!D408) -> 2.45 | D18: =IF(Productos!E408="","",Productos!E408) -> 2.65
A19: 411 | B19: =Productos!C409 -> Mini burger | C19: =IF(Productos!D409="","",Productos!D409) -> 3.35 | D19: =IF(Productos!E409="","",Productos!E409) -> 3.55
A20: 412 | B20: =Productos!C410 -> Mini de jamón ibérico | C20: =IF(Productos!D410="","",Productos!D410) -> 3.05 | D20: =IF(Productos!E410="","",Productos!E410) -> 3.25
A21: 413 | B21: =Productos!C411 -> Mini de ternera | C21: =IF(Productos!D411="","",Productos!D411) -> 2.95 | D21: =IF(Productos!E411="","",Productos!E411) -> 3.15
A22: 414 | B22: =Productos!C412 -> Mini + carajillo o caña | C22: =IF(Productos!D412="","",Productos!D412) -> 4.85 | D22: =IF(Productos!E412="","",Productos!E412) -> 5.05
A23: 415 | B23: =Productos!C413 -> Mini de tortilla de patata | C23: =IF(Productos!D413="","",Productos!D413) -> 3.1 | D23: =IF(Productos!E413="","",Productos!E413) -> 3.3
A24: 416 | B24: =Productos!C414 -> Mini caliente + refresco | C24: =IF(Productos!D414="","",Productos!D414) -> 3.85 | D24: =IF(Productos!E414="","",Productos!E414) -> 4.05
A25: 417 | B25: =Productos!C415 -> Desayuno Rafa | C25: =IF(Productos!D415="","",Productos!D415) -> 10.45 | D25: =IF(Productos!E415="","",Productos!E415) -> 10.65
A26: 418 | B26: =Productos!C416 -> Pan sin gluten | C26: =IF(Productos!D416="","",Productos!D416) -> 3.25 | D26: =IF(Productos!E416="","",Productos!E416) -> 3.45
A27: 419 | B27: =Productos!C417 -> Tostada con mermelada y mantequilla | C27: =IF(Productos!D417="","",Productos!D417) -> 2.45 | D27: =IF(Productos!E417="","",Productos!E417) -> 2.65
... A31: 423 | B31: =Productos!C421 -> Mini de salchicha del país | C31: =IF(Productos!D421="","",Productos!D421) -> 2.85 | D31: =IF(Productos!E421="","",Productos!E421) -> 3.05
A32: 424 | B32: =Productos!C422 -> Mini vegetal | C32: =IF(Productos!D422="","",Productos!D422) -> 3.25 | D32: =IF(Productos!E422="","",Productos!E422) -> 3.45 | E32: Revisar: aparece más de una vez con precios distintos
A33: 425 | B33: =Productos!C423 -> Bollería especial | C33: =IF(Productos!D423="","",Productos!D423) -> 2.3 | D33: =IF(Productos!E423="","",Productos!E423) -> 2.5
A34: 426 | B34: =Productos!C424 -> Mini de pechuga | C34: =IF(Productos!D424="","",Productos!D424) -> 2.85 | D34: =IF(Productos!E424="","",Productos!E424) -> 3.05
A35: 427 | B35: =Productos!C425 -> Tostada con tomate | C35: =IF(Productos!D425="","",Productos!D425) -> 2.25 | D35: =IF(Productos!E425="","",Productos!E425) -> 2.45
A36: 428 | B36: =Productos!C426 -> Mini de frankfurt | C36: =IF(Productos!D426="","",Productos!D426) -> 2.85 | D36: =IF(Productos!E426="","",Productos!E426) -> 3.05
A37: 429 | B37: =Productos!C427 -> Mini de butifarra blanca | C37: =IF(Productos!D427="","",Productos!D427) -> 2.95 | D37: =IF(Productos!E427="","",Productos!E427) -> 3.15
A38: 430 | B38: =Productos!C428 -> Mini de butifarra negra | C38: =IF(Productos!D428="","",Productos!D428) -> 2.95 | D38: =IF(Productos!E428="","",Productos!E428) -> 3.15
A39: 431 | B39: =Productos!C429 -> Donut | C39: =IF(Productos!D429="","",Productos!D429) -> 1.5 | D39: =IF(Productos!E429="","",Productos!E429) -> 1.7
A40: 432 | B40: =Productos!C430 -> Tarta de manzana | C40: =IF(Productos!D430="","",Productos!D430) -> 2.4 | D40: =IF(Productos!E430="","",Productos!E430) -> 2.6
